Workbook

Sheet Ipoteze
B2: MODEL FINANCIAR — INSTALAȚIE STAND-ALONE DE STOCARE ÎN BATERII
B3: Cramele Odobești SA — apel Fondul pentru modernizare, Ministerul Energiei
B4: CIORNĂ DE LUCRU. Celulele galbene se completează de utilizator. Restul se calculează automat.
B6: LEGENDĂ
B7: Albastru pe fond galben = date de intrare, se modifică
B8: Negru = formulă calculată în această foaie
B9: Verde = preluat din altă foaie
B11: 1. CONFIGURAȚIA TEHNICĂ
B12: Capacitate instalată | C12: 200 | D12: MWh | E12: Configurația Echilibrată din memoriu. Max analizat: 300 MWh
B13: Durata de stocare | C13: 4 | D13: ore | E13: Ghidul cere raport minim 2:1. Recomandat 4:1
B14: Putere instalată | C14: =C12/C13 | D14: MW | E14: Rezultă din capacitate și durată
B15: Randament dus-întors (RTE) | C15: 0.88 | E15: [DE COMPLETAT] din fișa tehnică a furnizorului
B16: Degradare anuală a capacității | C16: 0.02 | E16: [DE COMPLETAT] din garanția furnizorului
B17: Cicluri complete pe an | C17: 300 | D17: cicluri | E17: [DE COMPLETAT] din strategia de operare din studiul de fezabilitate
B18: Adâncime de descărcare utilizabilă | C18: 0.9 | E18: [DE COMPLETAT] din fișa tehnică
B20: 2. COST DE INVESTIȚIE — REPERE DE PIAȚĂ, NU OFERTE
B21: Curs de schimb USD/EUR | C21: 0.9 | D21: EUR/USD | E21: [DE COMPLETAT] cursul de la data ofertei
B22: Cost turnkey de referință | C22: 177000 | D22: USD/MWh | E22: Reper BNEF 2025 pentru Europa, sistem turnkey 4h. NU este ofertă.
B23: Cost turnkey de referință | C23: =C22*C21 | D23: EUR/MWh | E23: Convertit la cursul de mai sus. Valabil pentru configurația de referință 4h.
B25: Pondere cost legat de putere | C25: 0.14 | E25: [DE COMPLETAT] din structura ofertei. Cât din costul turnkey ține de PCS, trafo, celule MT — componente care scalează cu MW, nu cu MWh.
B26: Cost unitar de putere | C26: =C23*C12*C25/(C12/4) | D26: EUR/MW | E26: Derivat astfel încât totalul să reconcilieze cu reperul la 4 ore
B27: Cost unitar energetic | C27: =C23*(1-C25) | D27: EUR/MWh | E27: Celule, module, BMS, containere, climatizare — scalează cu MWh
B28: Cost echipamente BESS | C28: =C27*C12+C26*C14 | D28: EUR | E28: Componenta energetică plus componenta de putere. Aceasta este structura care face ca durata de stocare să conteze.
B30: Lungime traseu racord | C30: 4.4 | D30: km | E30: Variante din planșă: 4,40 / 5,70 / 6,00 / 7,30 km
B31: Cost unitar linie 110 kV | C31: 200000 | D31: EUR/km | E31: [DE COMPLETAT] din studiul de soluție. Valoare de test.
B32: Cost linie de racord | C32: =C30*C31 | D32: EUR | E32: Lungime x cost unitar
B33: Stație de conexiune 110 kV | C33: 30000 | D33: EUR/MW | E33: [DE COMPLETAT] din deviz. Scalează cu puterea racordată. Valoare de test.
B34: Cost stație de conexiune | C34: =C33*C14 | D34: EUR | E34: Putere x cost unitar
B35: Tarif de racordare | C35: 0 | D35: EUR | E35: [DE VERIFICAT] valoarea și eligibilitatea. Se completează după ATR.
B37: Construcții civile, platformă, drumuri | C37: 0.08 | D37: % din echipamente | E37: [DE COMPLETAT] din deviz
B38: Cost construcții civile | C38: =C37*C28 | D38: EUR
B39: Sisteme de siguranță și incendiu | C39: 0.05 | D39: % din echipamente | E39: [DE COMPLETAT] din scenariul ISU
B40: Cost sisteme de siguranță | C40: =C39*C28 | D40: EUR
B41: Proiectare, avize, consultanță | C41: 0.03 | D41: % din echipamente | E41: Probabil NEELIGIBIL [DE VERIFICAT]
B42: Cost proiectare și avize | C42: =C41*C28 | D42: EUR
B43: Neprevăzute | C43: 0.1 | D43: % din total | E43: Marjă de siguranță pe deviz
B45: 3. FINANȚARE
B46: Ofertă în procedura concurențială | C46: 55000 | D46: EUR/MWh | E46: CRITIC: criteriul unic de clasare. Cel mai mic câștigă.
B47: Plafon unitar reglementat | C47: 69000 | D47: EUR/MWh | E47: Din schema aprobată prin Ordinul 745/2026
B48: Plafon per întreprindere | C48: 15000000 | D48: EUR | E48: Din schema aprobată prin Ordinul 745/2026
...

Sheet CAPEX
B2: BUGETUL DE INVESTIȚIE
B3: Toate valorile derivă din foaia Ipoteze. Nu se scrie direct în această foaie.
B5: Categorie | C5: Valoare (EUR) | D5: EUR/MWh | E5: Eligibil | F5: Observație
B6: Echipamente BESS (celule, PCS, trafo, EMS) | C6: =Ipoteze!C28 | D6: =IFERROR(C6/Ipoteze!C12,0) | E6: DA | F6: Componenta majoritară
B7: Linie de racord 110 kV | C7: =Ipoteze!C32 | D7: =IFERROR(C7/Ipoteze!C12,0) | E7: [DE VERIFICAT] | F7: Depinde de traseul ales
B8: Stație de conexiune | C8: =Ipoteze!C34 | D8: =IFERROR(C8/Ipoteze!C12,0) | E8: DA | F8: [DE COMPLETAT] din deviz
B9: Tarif de racordare | C9: =Ipoteze!C35 | D9: =IFERROR(C9/Ipoteze!C12,0) | E9: [DE VERIFICAT] | F9: Se completează după ATR
B10: Construcții civile | C10: =Ipoteze!C38 | D10: =IFERROR(C10/Ipoteze!C12,0) | E10: DA
B11: Sisteme de siguranță și incendiu | C11: =Ipoteze!C40 | D11: =IFERROR(C11/Ipoteze!C12,0) | E11: DA | F11: Frecvent subestimat
B12: Proiectare, avize, consultanță | C12: =Ipoteze!C42 | D12: =IFERROR(C12/Ipoteze!C12,0) | E12: NU (probabil) | F12: [DE VERIFICAT] în ghid
B13: Subtotal | C13: =SUM(C6:C12) | D13: =C13/Ipoteze!C12
B14: Neprevăzute | C14: =C13*Ipoteze!C43 | D14: =C14/Ipoteze!C12
B16: TOTAL INVESTIȚIE | C16: =C13+C14 | D16: =C16/Ipoteze!C12
B17: Total cheltuieli eligibile (estimat) | C17: =C6+C8+C10+C11 | D17: =C17/Ipoteze!C12 | F17: Exclude proiectarea și, prudent, linia și tariful de racordare până la clarificare

Sheet Finantare
B2: STRUCTURA DE FINANȚARE ȘI TESTUL PLAFOANELOR
B4: Ajutor cerut = ofertă x capacitate | C4: =Ipoteze!C46*Ipoteze!C12 | D4: Produsul dintre oferta în EUR/MWh și MWh instalați
B5: Test 1: plafon unitar (69.000 EUR/MWh) | C5: =Ipoteze!C47*Ipoteze!C12 | D5: Ajutorul nu poate depăși această valoare
B6: Test 2: plafon per întreprindere | C6: =Ipoteze!C48 | D6: Ajutorul nu poate depăși 15 mil. EUR
B7: Test 3: 100% din cheltuielile eligibile | C7: =CAPEX!C17 | D7: Intensitatea nu poate depăși 100% din costurile eligibile
B8: AJUTOR ACORDABIL | C8: =MIN(C4,C5,C6,C7) | D8: Valoarea cea mai mică dintre cererea proprie și cele trei plafoane
B10: Contribuție proprie | C10: =CAPEX!C16-C8 | D10: Diferența dintre investiția totală și ajutor
B11: Ponderea ajutorului în investiția totală | C11: =IFERROR(C8/CAPEX!C16,0) | D11: Cât din proiect acoperă efectiv grantul
B12: Intensitate față de cheltuielile eligibile | C12: =IFERROR(C8/CAPEX!C17,0) | D12: Trebuie să fie sub 100%
B14: VERIFICĂRI
B15: Oferta este sub plafonul unitar? | C15: =IF(Ipoteze!C46<=Ipoteze!C47,"DA","NU — OFERTĂ NECONFORMĂ") | D15: Oferta peste 69.000 EUR/MWh este inadmisibilă
B16: Ajutorul acoperă cheltuielile eligibile? | C16: =IF(C8<=CAPEX!C17,"DA","NU — DEPĂȘEȘTE 100%") | D16: Ajutorul nu poate depăși costurile eligibile
B17: Raport capacitate/putere conform? | C17: =IF(Ipoteze!C13>=2,"DA","NU — SUB MINIMUL DE 2:1") | D17: Ghidul cere minimum 2 ore
B18: Putere peste minimul de 1 MW? | C18: =IF(Ipoteze!C14>=1,"DA","NU") | D18: Ghidul cere minimum 1 MW
B21: OBSERVAȚIE
B22: Cu reperele de cost europene, ajutorul acoperă o parte minoritară a investiției. Aceasta este premisa de planificare, nu o eroare de model.

Sheet CashFlow
B2: PROIECȚIA FLUXURILOR DE NUMERAR
B3: Anul 0 = investiția. Anii 1-15 = exploatare.
C5: An 0 | D5: An 1 | E5: An 2 | F5: An 3 | G5: An 4 | H5: An 5 | I5: An 6 | J5: An 7 | K5: An 8 | L5: An 9 | M5: An 10 | N5: An 11 | O5: An 12 | P5: An 13 | Q5: An 14 | R5: An 15
B7: Energie descărcată (MWh/an) | C7: 0 | D7: =Ipoteze!C12*Ipoteze!C18*Ipoteze!C17*(1-Ipoteze!C16)^1 | E7: =Ipoteze!C12*Ipoteze!C18*Ipoteze!C17*(1-Ipoteze!C16)^2 | F7: =Ipoteze!C12*Ipoteze!C18*Ipoteze!C17*(1-Ipoteze!C16)^3 | G7: =Ipoteze!C12*Ipoteze!C18*Ipoteze!C17*(1-Ipoteze!C16)^4 | H7: =Ipoteze!C12*Ipoteze!C18*Ipoteze!C17*(1-Ipoteze!C16)^5 | I7: =Ipoteze!C12*Ipoteze!C18*Ipoteze!C17*(1-Ipoteze!C16)^6 | J7: =Ipoteze!C12*Ipoteze!C18*Ipoteze!C17*(1-Ipoteze!C16)^7 | K7: =Ipoteze!C12*Ipoteze!C18*Ipoteze!C17*(1-Ipoteze!C16)^8 | L7: =Ipoteze!C12*Ipoteze!C18*Ipoteze!C17*(1-Ipoteze!C16)^9 | M7: =Ipoteze!C12*Ipoteze!C18*Ipoteze!C17*(1-Ipoteze!C16)^10 | N7: =Ipoteze!C12*Ipoteze!C18*Ipoteze!C17*(1-Ipoteze!C16)^11 | O7: =Ipoteze!C12*Ipoteze!C18*Ipoteze!C17*(1-Ipoteze!C16)^12 | P7: =Ipoteze!C12*Ipoteze!C18*Ipoteze!C17*(1-Ipoteze!C16)^13 | Q7: =Ipoteze!C12*Ipoteze!C18*Ipoteze!C17*(1-Ipoteze!C16)^14 | R7: =Ipoteze!C12*Ipoteze!C18*Ipoteze!C17*(1-Ipoteze!C16)^15
B8: Venit din arbitraj | C8: 0 | D8: =D7*Ipoteze!C51*(1+Ipoteze!C55)^1 | E8: =E7*Ipoteze!C51*(1+Ipoteze!C55)^2 | F8: =F7*Ipoteze!C51*(1+Ipoteze!C55)^3 | G8: =G7*Ipoteze!C51*(1+Ipoteze!C55)^4 | H8: =H7*Ipoteze!C51*(1+Ipoteze!C55)^5 | I8: =I7*Ipoteze!C51*(1+Ipoteze!C55)^6 | J8: =J7*Ipoteze!C51*(1+Ipoteze!C55)^7 | K8: =K7*Ipoteze!C51*(1+Ipoteze!C55)^8 | L8: =L7*Ipoteze!C51*(1+Ipoteze!C55)^9 | M8: =M7*Ipoteze!C51*(1+Ipoteze!C55)^10 | N8: =N7*Ipoteze!C51*(1+Ipoteze!C55)^11 | O8: =O7*Ipoteze!C51*(1+Ipoteze!C55)^12 | P8: =P7*Ipoteze!C51*(1+Ipoteze!C55)^13 | Q8: =Q7*Ipoteze!C51*(1+Ipoteze!C55)^14 | R8: =R7*Ipoteze!C51*(1+Ipoteze!C55)^15
B9: Venit din servicii de sistem | C9: 0 | D9: =Ipoteze!C14*Ipoteze!C52*(1+Ipoteze!C55)^1 | E9: =Ipoteze!C14*Ipoteze!C52*(1+Ipoteze!C55)^2 | F9: =Ipoteze!C14*Ipoteze!C52*(1+Ipoteze!C55)^3 | G9: =Ipoteze!C14*Ipoteze!C52*(1+Ipoteze!C55)^4 | H9: =Ipoteze!C14*Ipoteze!C52*(1+Ipoteze!C55)^5 | I9: =Ipoteze!C14*Ipoteze!C52*(1+Ipoteze!C55)^6 | J9: =Ipoteze!C14*Ipoteze!C52*(1+Ipoteze!C55)^7 | K9: =Ipoteze!C14*Ipoteze!C52*(1+Ipoteze!C55)^8 | L9: =Ipoteze!C14*Ipoteze!C52*(1+Ipoteze!C55)^9 | M9: =Ipoteze!C14*Ipoteze!C52*(1+Ipoteze!C55)^10 | N9: =Ipoteze!C14*Ipoteze!C52*(1+Ipoteze!C55)^11 | O9: =Ipoteze!C14*Ipoteze!C52*(1+Ipoteze!C55)^12 | P9: =Ipoteze!C14*Ipoteze!C52*(1+Ipoteze!C55)^13 | Q9: =Ipoteze!C14*Ipoteze!C52*(1+Ipoteze!C55)^14 | R9: =Ipoteze!C14*Ipoteze!C52*(1+Ipoteze!C55)^15
B10: Costuri de rețea și consum tehnologic | C10: 0 | D10: =-D7*Ipoteze!C53*(1+Ipoteze!C55)^1 | E10: =-E7*Ipoteze!C53*(1+Ipoteze!C55)^2 | F10: =-F7*Ipoteze!C53*(1+Ipoteze!C55)^3 | G10: =-G7*Ipoteze!C53*(1+Ipoteze!C55)^4 | H10: =-H7*Ipoteze!C53*(1+Ipoteze!C55)^5 | I10: =-I7*Ipoteze!C53*(1+Ipoteze!C55)^6 | J10: =-J7*Ipoteze!C53*(1+Ipoteze!C55)^7 | K10: =-K7*Ipoteze!C53*(1+Ipoteze!C55)^8 | L10: =-L7*Ipoteze!C53*(1+Ipoteze!C55)^9 | M10: =-M7*Ipoteze!C53*(1+Ipoteze!C55)^10 | N10: =-N7*Ipoteze!C53*(1+Ipoteze!C55)^11 | O10: =-O7*Ipoteze!C53*(1+Ipoteze!C55)^12 | P10: =-P7*Ipoteze!C53*(1+Ipoteze!C55)^13 | Q10: =-Q7*Ipoteze!C53*(1+Ipoteze!C55)^14 | R10: =-R7*Ipoteze!C53*(1+Ipoteze!C55)^15
B11: Costuri O&M | C11: 0 | D11: =-CAPEX!$C$16*Ipoteze!C54*(1+Ipoteze!C55)^1 | E11: =-CAPEX!$C$16*Ipoteze!C54*(1+Ipoteze!C55)^2 | F11: =-CAPEX!$C$16*Ipoteze!C54*(1+Ipoteze!C55)^3 | G11: =-CAPEX!$C$16*Ipoteze!C54*(1+Ipoteze!C55)^4 | H11: =-CAPEX!$C$16*Ipoteze!C54*(1+Ipoteze!C55)^5 | I11: =-CAPEX!$C$16*Ipoteze!C54*(1+Ipoteze!C55)^6 | J11: =-CAPEX!$C$16*Ipoteze!C54*(1+Ipoteze!C55)^7 | K11: =-CAPEX!$C$16*Ipoteze!C54*(1+Ipoteze!C55)^8 | L11: =-CAPEX!$C$16*Ipoteze!C54*(1+Ipoteze!C55)^9 | M11: =-CAPEX!$C$16*Ipoteze!C54*(1+Ipoteze!C55)^10 | N11: =-CAPEX!$C$16*Ipoteze!C54*(1+Ipoteze!C55)^11 | O11: =-CAPEX!$C$16*Ipoteze!C54*(1+Ipoteze!C55)^12 | P11: =-CAPEX!$C$16*Ipoteze!C54*(1+Ipoteze!C55)^13 | Q11: =-CAPEX!$C$16*Ipoteze!C54*(1+Ipoteze!C55)^14 | R11: =-CAPEX!$C$16*Ipoteze!C54*(1+Ipoteze!C55)^15
B12: EBITDA | C12: 0 | D12: =SUM(D8:D11) | E12: =SUM(E8:E11) | F12: =SUM(F8:F11) | G12: =SUM(G8:G11) | H12: =SUM(H8:H11) | I12: =SUM(I8:I11) | J12: =SUM(J8:J11) | K12: =SUM(K8:K11) | ... R12: =SUM(R8:R11)
B13: Amortizare | C13: 0 | D13: =IF(1<=Ipoteze!C61,-CAPEX!$C$16/Ipoteze!C61,0) | E13: =IF(2<=Ipoteze!C61,-CAPEX!$C$16/Ipoteze!C61,0) | F13: =IF(3<=Ipoteze!C61,-CAPEX!$C$16/Ipoteze!C61,0) | G13: =IF(4<=Ipoteze!C61,-CAPEX!$C$16/Ipoteze!C61,0) | H13: =IF(5<=Ipoteze!C61,-CAPEX!$C$16/Ipoteze!C61,0) | I13: =IF(6<=Ipoteze!C61,-CAPEX!$C$16/Ipoteze!C61,0) | J13: =IF(7<=Ipoteze!C61,-CAPEX!$C$16/Ipoteze!C61,0) | K13: =IF(8<=Ipoteze!C61,-CAPEX!$C$16/Ipoteze!C61,0) | L13: =IF(9<=Ipoteze!C61,-CAPEX!$C$16/Ipoteze!C61,0) | M13: =IF(10<=Ipoteze!C61,-CAPEX!$C$16/Ipoteze!C61,0) | N13: =IF(11<=Ipoteze!C61,-CAPEX!$C$16/Ipoteze!C61,0) | O13: =IF(12<=Ipoteze!C61,-CAPEX!$C$16/Ipoteze!C61,0) | P13: =IF(13<=Ipoteze!C61,-CAPEX!$C$16/Ipoteze!C61,0) | Q13: =IF(14<=Ipoteze!C61,-CAPEX!$C$16/Ipoteze!C61,0) | R13: =IF(15<=Ipoteze!C61,-CAPEX!$C$16/Ipoteze!C61,0)
B14: Profit brut | C14: 0 | D14: =D12+D13 | E14: =E12+E13 | F14: =F12+F13 | G14: =G12+G13 | H14: =H12+H13 | I14: =I12+I13 | J14: =J12+J13 | K14: =K12+K13 | ... R14: =R12+R13
B15: Impozit pe profit | C15: 0 | D15: =-MAX(0,D14)*Ipoteze!C60 | E15: =-MAX(0,E14)*Ipoteze!C60 | F15: =-MAX(0,F14)*Ipoteze!C60 | G15: =-MAX(0,G14)*Ipoteze!C60 | H15: =-MAX(0,H14)*Ipoteze!C60 | I15: =-MAX(0,I14)*Ipoteze!C60 | J15: =-MAX(0,J14)*Ipoteze!C60 | K15: =-MAX(0,K14)*Ipoteze!C60 | L15: =-MAX(0,L14)*Ipoteze!C60 | M15: =-MAX(0,M14)*Ipoteze!C60 | N15: =-MAX(0,N14)*Ipoteze!C60 | O15: =-MAX(0,O14)*Ipoteze!C60 | P15: =-MAX(0,P14)*Ipoteze!C60 | Q15: =-MAX(0,Q14)*Ipoteze!C60 | R15: =-MAX(0,R14)*Ipoteze!C60
B16: Profit net | C16: 0 | D16: =D14+D15 | E16: =E14+E15 | F16: =F14+F15 | G16: =G14+G15 | H16: =H14+H15 | I16: =I14+I15 | J16: =J14+J15 | K16: =K14+K15 | ... R16: =R14+R15
B18: Investiție | C18: =-CAPEX!C16
B19: Grant încasat | C19: =Finantare!C8
B21: FLUX DE NUMERAR NET | C21: =C18+C19 | D21: =D12+D15 | E21: =E12+E15 | F21: =F12+F15 | G21: =G12+G15 | H21: =H12+H15 | I21: =I12+I15 | J21: =J12+J15 | K21: =K12+K15 | ... R21: =R12+R15
B22: Flux cumulat | C22: =C21 | D22: =C22+D21 | E22: =D22+E21 | F22: =E22+F21 | G22: =F22+G21 | H22: =G22+H21 | I22: =H22+I21 | J22: =I22+J21 | K22: =J22+K21 | ... R22: =Q22+R21

Sheet Rezultate
B2: INDICATORI DE PERFORMANȚĂ
B3: Rezultatele sunt valide doar în măsura în care ipotezele sunt reale. Cu valorile de test actuale, ele indică ordine de mărime, nu prognoze.
B5: Investiție totală | C5: =CAPEX!C16 | D5: Din foaia CAPEX
B6: Cost unitar al investiției | C6: =CAPEX!C16/Ipoteze!C12 | D6: EUR/MWh instalat
B7: Grant obținut | C7: =Finantare!C8 | D7: După aplicarea celor trei plafoane
B8: Contribuție proprie necesară | C8: =Finantare!C10 | D8: Suma care trebuie asigurată din surse proprii sau atrase
B9: Ponderea grantului | C9: =IFERROR(Finantare!C8/CAPEX!C16,0) | D9: Cât din investiție acoperă ajutorul
B11: EBITDA an 1 | C11: =CashFlow!D12 | D11: Primul an de exploatare
B12: VAN al proiectului | C12: =NPV(Ipoteze!C59,CashFlow!D21:R21)+CashFlow!C21 | D12: Valoare actualizată netă, incluzând grantul
B13: RIR al proiectului | C13: =IFERROR(IRR(CashFlow!C21:R21),0) | D13: Rata internă de rentabilitate
B14: Termen de recuperare simplu | C14: =IFERROR(MATCH(0,CashFlow!C22:R22,1),0) | D14: Anul în care fluxul cumulat devine pozitiv
B17: SENZITIVITATE: OFERTA ÎN EUR/MWh
B18: Modificați oferta în Ipoteze și urmăriți efectul asupra contribuției proprii și a RIR.
B20: Ofertă (EUR/MWh) | C20: Ajutor (EUR) | D20: Contribuție proprie (EUR)
B21: 40000 | C21: =MIN(B21*Ipoteze!C12,Ipoteze!C48,CAPEX!C17) | D21: =CAPEX!C16-C21
B22: 45000 | C22: =MIN(B22*Ipoteze!C12,Ipoteze!C48,CAPEX!C17) | D22: =CAPEX!C16-C22
B23: 50000 | C23: =MIN(B23*Ipoteze!C12,Ipoteze!C48,CAPEX!C17) | D23: =CAPEX!C16-C23
B24: 55000 | C24: =MIN(B24*Ipoteze!C12,Ipoteze!C48,CAPEX!C17) | D24: =CAPEX!C16-C24
B25: 60000 | C25: =MIN(B25*Ipoteze!C12,Ipoteze!C48,CAPEX!C17) | D25: =CAPEX!C16-C25
B26: 65000 | C26: =MIN(B26*Ipoteze!C12,Ipoteze!C48,CAPEX!C17) | D26: =CAPEX!C16-C26
B27: 69000 | C27: =MIN(B27*Ipoteze!C12,Ipoteze!C48,CAPEX!C17) | D27: =CAPEX!C16-C27
B30: AVERTISMENT
B31: Acest model NU contine oferte reale. Costurile sunt repere internationale de piata, iar spread-ul si serviciile de sistem sunt valori de test.
B32: Nicio decizie de investitie sau de ofertare nu trebuie luata pe baza acestor cifre.
B33: Modelul devine utilizabil dupa completarea celulelor galbene cu date din oferte, din studiul de solutie si din analiza de piata.

Sheet Scenarii
B2: COMPARAȚIA SCENARIILOR TEHNICO-ECONOMICE
B3: Aceeași capacitate instalată, durate diferite de stocare. Cerință a studiului de fezabilitate conform H.G. 907/2016.
B5: Element | C5: Scenariul 1 (4h) | D5: Scenariul 2 (2h) | E5: Diferență | F5: Observație
B6: Capacitate instalată (MWh) | C6: =Ipoteze!C12 | D6: =Ipoteze!C12 | E6: =D6-C6 | F6: Identică prin construcție
B7: Durata de stocare (ore) | C7: 4 | D7: 2 | E7: =D7-C7 | F7: Scenariul 2 este la minimul admis de ghid
B8: Putere instalată (MW) | C8: =C6/C7 | D8: =D6/D7 | E8: =D8-C8 | F8: Rezultă din capacitate și durată
B10: Cost componentă energetică | C10: =C6*Ipoteze!C27 | D10: =D6*Ipoteze!C27 | E10: =D10-C10 | F10: Identic — depinde doar de MWh
B11: Cost componentă de putere | C11: =C8*Ipoteze!C26 | D11: =D8*Ipoteze!C26 | E11: =D11-C11 | F11: Scenariul 2 are putere dublă
B12: Stație de conexiune | C12: =C8*Ipoteze!C33 | D12: =D8*Ipoteze!C33 | E12: =D12-C12 | F12: Scalează cu puterea racordată
B13: Linie de racord | C13: =Ipoteze!C32 | D13: =Ipoteze!C32 | E13: =D13-C13 | F13: Identică — același traseu
B14: Construcții civile | C14: =(C10+C11)*Ipoteze!C37 | D14: =(D10+D11)*Ipoteze!C37 | E14: =D14-C14 | F14: Procent din echipamente
B15: Sisteme de siguranță | C15: =(C10+C11)*Ipoteze!C39 | D15: =(D10+D11)*Ipoteze!C39 | E15: =D15-C15 | F15: Procent din echipamente
B16: Proiectare și avize | C16: =(C10+C11)*Ipoteze!C41 | D16: =(D10+D11)*Ipoteze!C41 | E16: =D16-C16 | F16: Probabil neeligibil
B17: Neprevăzute | C17: =SUM(C10:C16)*Ipoteze!C43 | D17: =SUM(D10:D16)*Ipoteze!C43 | E17: =D17-C17 | F17: Marjă pe deviz
B18: TOTAL INVESTIȚIE | C18: =SUM(C10:C17) | D18: =SUM(D10:D17) | E18: =D18-C18 | F18: Suma tuturor categoriilor
B19: Cost unitar (EUR/MWh instalat) | C19: =C18/C6 | D19: =D18/D6 | E19: =D19-C19 | F19: Baza pentru stabilirea ofertei
B21: Ajutor la oferta din Ipoteze | C21: =MIN(Ipoteze!C46*C6,Ipoteze!C48,Ipoteze!C47*C6) | D21: =MIN(Ipoteze!C46*D6,Ipoteze!C48,Ipoteze!C47*D6) | E21: =D21-C21 | F21: Identic — ajutorul se calculează pe MWh, nu pe MW
B22: Contribuție proprie | C22: =C18-C21 | D22: =D18-D21 | E22: =D22-C22 | F22: Diferența rămasă de acoperit
B23: Ponderea ajutorului | C23: =IFERROR(C21/C18,0) | D23: =IFERROR(D21/D18,0) | F23: Cât acoperă grantul din investiție
B25: Plafonul de 69.000 acoperă din cost unitar | C25: =IFERROR(Ipoteze!C47/C19,0) | D25: =IFERROR(Ipoteze!C47/D19,0) | F25: Cât din costul unitar poate acoperi cel mult plafonul reglementat
B27: Energie descărcată an 1 (MWh) | C27: =C6*Ipoteze!C18*Ipoteze!C17 | D27: =D6*Ipoteze!C18*Ipoteze!C17 | E27: =D27-C27 | F27: La același număr de cicluri
B28: Venit brut din arbitraj an 1 | C28: =C27*Ipoteze!C51 | D28: =D27*Ipoteze!C51 | E28: =D28-C28 | F28: ATENȚIE: spreadul valorificabil diferă între 4h și 2h. [DE COMPLETAT] din analiza de piață
B29: Costuri O&M an 1 | C29: =-C18*Ipoteze!C54 | D29: =-D18*Ipoteze!C54 | E29: =D29-C29 | F29: Procent din investiție
B30: EBITDA an 1 | C30: =C28+C29 | D30: =D28+D29 | E30: =D30-C30 | F30: Fără serviciile de sistem
B31: Termen simplu de recuperare (ani) | C31: =IFERROR(C22/C30,0) | D31: =IFERROR(D22/D30,0) | F31: Contribuție proprie împărțită la EBITDA
B34: CONCLUZIA COMPARAȚIEI
B35: Ajutorul de stat este identic in cele doua scenarii, pentru ca se calculeaza pe MWh instalati. Diferenta se manifesta integral pe partea de costuri.
B36: Scenariul 2 are aceeasi capacitate, deci acelasi grant maxim, dar putere dubla — deci costuri mai mari de conversie si de racordare.
B37: Rezulta un cost unitar mai mare pe MWh, deci o pozitie mai slaba intr-o licitatie departajata exclusiv pe euro/MWh.
B38: ATENTIE la randul de venituri: modelul aplica acelasi spread ambelor scenarii, ceea ce favorizeaza artificial scenariul 2. In realitate un sistem de 2 ore valorifica un spread diferit. Se corecteaza dupa analiza de piata.

Sheet ScenariuChina
B2: SCENARIU ALTERNATIV: REPER DE COST DIN CHINA
B3: Recalculează bugetul, finanțarea și fluxul de numerar cu un reper de cost turnkey din China, păstrând toate celelalte ipoteze din foaia Ipoteze neschimbate (capacitate, putere, spread, cicluri, rata de actualizare etc.).
B4: CIORNĂ DE LUCRU. Celula galbenă de mai jos se completează de utilizator. Restul se calculează automat.
B6: 1. IPOTEZĂ DE COST ALTERNATIVĂ
B7: Cost turnkey referință China | C7: 73000 | D7: USD/MWh | E7: Reper BNEF/Ember 2025-2026 pentru sisteme turnkey China. NU este ofertă. Comparație: Ipoteze!C22 = reper Europa (177.000 USD/MWh).
B8: Cost turnkey referință China | C8: =C7*Ipoteze!C21 | D8: EUR/MWh | E8: Convertit la cursul din Ipoteze!C21
B10: 2. BUGET DE INVESTIȚIE RECALCULAT
B11: Cost unitar de putere | C11: =C8*Ipoteze!C12*Ipoteze!C25/(Ipoteze!C12/Ipoteze!C13) | D11: EUR/MW
B12: Cost unitar energetic | C12: =C8*(1-Ipoteze!C25) | D12: EUR/MWh
B13: Cost echipamente BESS | C13: =C12*Ipoteze!C12+C11*Ipoteze!C14 | D13: EUR
B14: Linie de racord 110 kV | C14: =Ipoteze!C32 | D14: EUR | E14: Neschimbat față de scenariul de referință
B15: Stație de conexiune | C15: =Ipoteze!C34 | D15: EUR
B16: Tarif de racordare | C16: =Ipoteze!C35 | D16: EUR
B17: Construcții civile | C17: =Ipoteze!C37*C13 | D17: EUR
B18: Sisteme de siguranță și incendiu | C18: =Ipoteze!C39*C13 | D18: EUR
B19: Proiectare, avize, consultanță | C19: =Ipoteze!C41*C13 | D19: EUR
B20: Subtotal | C20: =SUM(C13:C19)
B21: Neprevăzute | C21: =C20*Ipoteze!C43
B22: TOTAL INVESTIȚIE | C22: =C20+C21
B23: Cost unitar al investiției | C23: =IFERROR(C22/Ipoteze!C12,0) | D23: EUR/MWh instalat
B24: Total cheltuieli eligibile (estimat) | C24: =C13+C15+C17+C18 | E24: Exclude proiectarea și, prudent, linia și tariful de racordare, ca în foaia CAPEX
B26: 3. FINANȚARE
B27: Ajutor cerut = ofertă x capacitate | C27: =Ipoteze!C46*Ipoteze!C12
B28: Test 1: plafon unitar (Ipoteze!C47) | C28: =Ipoteze!C47*Ipoteze!C12
B29: Test 2: plafon per întreprindere | C29: =Ipoteze!C48
B30: Test 3: 100% din cheltuielile eligibile | C30: =C24
B31: AJUTOR ACORDABIL | C31: =MIN(C27,C28,C29,C30)
B32: Contribuție proprie | C32: =C22-C31
B34: 4. FLUX DE NUMERAR (ani 0-15)
C35: An 0 | D35: An 1 | E35: An 2 | F35: An 3 | G35: An 4 | H35: An 5 | I35: An 6 | J35: An 7 | K35: An 8 | L35: An 9 | M35: An 10 | N35: An 11 | O35: An 12 | P35: An 13 | Q35: An 14 | R35: An 15
B36: Energie descărcată (MWh/an) | C36: 0 | D36: =CashFlow!D7 | E36: =CashFlow!E7 | F36: =CashFlow!F7 | G36: =CashFlow!G7 | H36: =CashFlow!H7 | I36: =CashFlow!I7 | J36: =CashFlow!J7 | K36: =CashFlow!K7 | ... R36: =CashFlow!R7
B37: Venit din arbitraj | C37: 0 | D37: =CashFlow!D8 | E37: =CashFlow!E8 | F37: =CashFlow!F8 | G37: =CashFlow!G8 | H37: =CashFlow!H8 | I37: =CashFlow!I8 | J37: =CashFlow!J8 | K37: =CashFlow!K8 | ... R37: =CashFlow!R8
B38: Venit din servicii de sistem | C38: 0 | D38: =CashFlow!D9 | E38: =CashFlow!E9 | F38: =CashFlow!F9 | G38: =CashFlow!G9 | H38: =CashFlow!H9 | I38: =CashFlow!I9 | J38: =CashFlow!J9 | K38: =CashFlow!K9 | ... R38: =CashFlow!R9
B39: Costuri de rețea și consum tehnologic | C39: 0 | D39: =CashFlow!D10 | E39: =CashFlow!E10 | F39: =CashFlow!F10 | G39: =CashFlow!G10 | H39: =CashFlow!H10 | I39: =CashFlow!I10 | J39: =CashFlow!J10 | K39: =CashFlow!K10 | ... R39: =CashFlow!R10
B40: Costuri O&M (recalculate cu noul TOTAL) | C40: 0 | D40: =-$C$22*Ipoteze!C54*(1+Ipoteze!C55)^1 | E40: =-$C$22*Ipoteze!C54*(1+Ipoteze!C55)^2 | F40: =-$C$22*Ipoteze!C54*(1+Ipoteze!C55)^3 | G40: =-$C$22*Ipoteze!C54*(1+Ipoteze!C55)^4 | H40: =-$C$22*Ipoteze!C54*(1+Ipoteze!C55)^5 | I40: =-$C$22*Ipoteze!C54*(1+Ipoteze!C55)^6 | J40: =-$C$22*Ipoteze!C54*(1+Ipoteze!C55)^7 | K40: =-$C$22*Ipoteze!C54*(1+Ipoteze!C55)^8 | L40: =-$C$22*Ipoteze!C54*(1+Ipoteze!C55)^9 | M40: =-$C$22*Ipoteze!C54*(1+Ipoteze!C55)^10 | N40: =-$C$22*Ipoteze!C54*(1+Ipoteze!C55)^11 | O40: =-$C$22*Ipoteze!C54*(1+Ipoteze!C55)^12 | P40: =-$C$22*Ipoteze!C54*(1+Ipoteze!C55)^13 | Q40: =-$C$22*Ipoteze!C54*(1+Ipoteze!C55)^14 | R40: =-$C$22*Ipoteze!C54*(1+Ipoteze!C55)^15
B41: EBITDA | C41: 0 | D41: =SUM(D37:D40) | E41: =SUM(E37:E40) | F41: =SUM(F37:F40) | G41: =SUM(G37:G40) | H41: =SUM(H37:H40) | I41: =SUM(I37:I40) | J41: =SUM(J37:J40) | K41: =SUM(K37:K40) | ... R41: =SUM(R37:R40)
B42: Amortizare | C42: 0 | D42: =IF(1<=Ipoteze!C61,-$C$22/Ipoteze!C61,0) | E42: =IF(2<=Ipoteze!C61,-$C$22/Ipoteze!C61,0) | F42: =IF(3<=Ipoteze!C61,-$C$22/Ipoteze!C61,0) | G42: =IF(4<=Ipoteze!C61,-$C$22/Ipoteze!C61,0) | H42: =IF(5<=Ipoteze!C61,-$C$22/Ipoteze!C61,0) | I42: =IF(6<=Ipoteze!C61,-$C$22/Ipoteze!C61,0) | J42: =IF(7<=Ipoteze!C61,-$C$22/Ipoteze!C61,0) | K42: =IF(8<=Ipoteze!C61,-$C$22/Ipoteze!C61,0) | L42: =IF(9<=Ipoteze!C61,-$C$22/Ipoteze!C61,0) | M42: =IF(10<=Ipoteze!C61,-$C$22/Ipoteze!C61,0) | N42: =IF(11<=Ipoteze!C61,-$C$22/Ipoteze!C61,0) | O42: =IF(12<=Ipoteze!C61,-$C$22/Ipoteze!C61,0) | P42: =IF(13<=Ipoteze!C61,-$C$22/Ipoteze!C61,0) | Q42: =IF(14<=Ipoteze!C61,-$C$22/Ipoteze!C61,0) | R42: =IF(15<=Ipoteze!C61,-$C$22/Ipoteze!C61,0)
B43: Profit brut | C43: 0 | D43: =D41+D42 | E43: =E41+E42 | F43: =F41+F42 | G43: =G41+G42 | H43: =H41+H42 | I43: =I41+I42 | J43: =J41+J42 | K43: =K41+K42 | ... R43: =R41+R42
B44: Impozit pe profit | C44: 0 | D44: =-MAX(0,D43)*Ipoteze!C60 | E44: =-MAX(0,E43)*Ipoteze!C60 | F44: =-MAX(0,F43)*Ipoteze!C60 | G44: =-MAX(0,G43)*Ipoteze!C60 | H44: =-MAX(0,H43)*Ipoteze!C60 | I44: =-MAX(0,I43)*Ipoteze!C60 | J44: =-MAX(0,J43)*Ipoteze!C60 | K44: =-MAX(0,K43)*Ipoteze!C60 | L44: =-MAX(0,L43)*Ipoteze!C60 | M44: =-MAX(0,M43)*Ipoteze!C60 | N44: =-MAX(0,N43)*Ipoteze!C60 | O44: =-MAX(0,O43)*Ipoteze!C60 | P44: =-MAX(0,P43)*Ipoteze!C60 | Q44: =-MAX(0,Q43)*Ipoteze!C60 | R44: =-MAX(0,R43)*Ipoteze!C60
B45: Profit net | C45: 0 | D45: =D43+D44 | E45: =E43+E44 | F45: =F43+F44 | G45: =G43+G44 | H45: =H43+H44 | I45: =I43+I44 | J45: =J43+J44 | K45: =K43+K44 | ... R45: =R43+R44
...
